Workbook

Sheet инвойс 1
B1: 杭 州 中 纺 进 出 口 有 限 公 司
B2: HANGZHOU ZHONGFANG TEXTILE IMP./EXP. CO., LTD.
B3: NO.756-2,RENMIN AVENUE,NANYUAN STREET, LINPING DISTRICT,HANGZHOU, ZHEJIANG PROVINCE CHINA, tel: +86-571-86255881, E-mail: liuzhihui@zhongfanghz.cn
B4: www.zhongfanghz.cn
B7: ="SPECIFICATION №"&L9&" dd "&L11 -> SPECIFICATION №ZFRMB26148-626-1 dd Aug.19,2026
K9: инв номер: | L9: ZFRMB26148-626-1
B10: Contract/Контракт №：SM-LU2 dated 23.11.2018
K11: дата: | L11: Aug.19,2026
B13: Buyer/Покупатель: | I13: Seller / Продавец:
B14: “SM REGIONTEKSTIL'” LLC / “СМ Регионтекстиль” ООО | I14: HANGZHOU ZHONGFANG TEXTILE IMP./EXP. CO., LTD.
B15: Address/Адрес: | I15: Address/Адрес:
B16: 143421 Moscow region, city of Krasnogorsk, 21st kilometer of Baltiya highway, comp. 2, bld. 1, prem. 1, OGRN 1175024014472, TIN 5032281280, KPP 502401001 | I16: NO.756-2,RENMIN AVENUE,NANYUAN STREET, LINPING DISTRICT,HANGZHOU, ZHEJIANG PROVINCE CHINA, tel: +86-571-86255881, E-mail: liuzhihui@zhongfanghz.cn
B17: 143421, МОСКОВСКАЯ ОБЛАСТЬ, Г.О. КРАСНОГОРСК, ТЕР. АВТОДОРОГА БАЛТИЯ, КМ 21-Й, Д. 2, СТР. 1, ПОМЕЩ. 1, ОГРН 1175024014472, ИНН 5032281280, КПП 502401001
B18: Terms of payment/Условия оплаты: 100% payment during 120 days after shipment / 100% оплата в течении 120 дней со дня поставки. | I18: Manufactor / Производитель:
B19: Terms of delivery/Условия поставки: EXW Hangzhou, China / EXW Hangzhou, Китай | I19: HANGZHOU ZHONGFANG TEXTILE IMP./EXP. CO., LTD.
B20: Delivery date/Сроки поставки: not later than/не позднее 19.09.2026
B22: № | C22: Q-Ty Rolls / Кол-во рулонов | D22: Art./Артикул | E22: Product name / Наименование товара | F22: HS code / Код гармонизированной системы | G22: Customs code / Таможенный код | H22: Q-ty meters / Кол-во погонных метров | I22: Widht, m / Ширина, м | J22: Q-ty m2 / Кол-во кв.м | K22: N.W, kg / Вес Нетто, кг | L22: G.W, kg / Вес Брутто, кг | M22: Price per meter ￥/ Цена за пог. метр, Юань | N22: Total price, Y / Цена, Юань | S22: дизайн | T22: тнвэд | U22: рол | V22: ширина рол | W22: итого м2 | X22: метры пог | Y22: цена за м | Z22: тотал | AA22: нет | AB22: гросс | AG22: ТМ
B23: 1 | C23: =U23 -> 8 | D23: =S23 -> Melange 928 | E23: =R23 -> Upholstery fabric from textured polyether yarns of different colors, made from: polyester - 100%. Ткань мебельная обивочная из текстурированных полиэфирных нитей разных цветов, состав полиэстер 100% | F23: =T23 -> 5407530000 | G23: =O23 -> 5407530000 | H23: =X23 -> 302.9 | I23: =V23 -> 1.41 | J23: =W23 -> 427.089 | K23: =ROUND(AA23,2) -> 209 | L23: =ROUND(AB23,2) -> 219 | M23: =Y23 -> 22.5 | N23: =ROUND(Z23,2) -> 6815.25 | O23: 5407530000 | P23: КИТАЙ | Q23: HANGZHOU ZHONGFANG TEXTILE IMP/EXP.CO.,LTD | R23: Upholstery fabric from textured polyether yarns of different colors, made from: polyester - 100%. Ткань мебельная обивочная из текстурированных полиэфирных нитей разных цветов, состав полиэстер 100% | S23: Melange 928 | T23: 5407530000 | U23: 8 | V23: 1.41 | W23: 427.089 | X23: 302.9 | Y23: 22.5 | Z23: =X23*Y23 -> 6815.25 | AA23: 209.001 | AB23: 219.001 | AC23: 01402 | AD23: ЕАЭС N RU Д-CN.РА02.В.67501/25 | AE23: 45742 | AF23: 47548 | AG23: HANGZHOU ZHONGFANG TEXTILE IMP./EXP. CO., LTD.
B24: 2 | C24: =U24 -> 15 | D24: =S24 -> Noble 110 | E24: =R24 -> FABRICS CONTAINING 85 % BY WT OR MORE OF NON-TEXTURED POLYESTER DYED YARNS: FABRIC FOR FURNITURE (BOUCLET) . composition 100% polyester/ТКАНИ СОДЕРЖАЩИЕ 85 МАС.% ИЛИ БОЛЕЕ НЕТЕКСТУРИРОВАННЫХ ПОЛИЭФИРНЫХ ОКРАШЕННЫХ НИТЕЙ: ТКАНЬ ДЛЯ МЕБЕЛИ (БУКЛЕ) . состав 100% полиэстер | F24: =T24 -> 5407610000 | G24: =O24 -> 5407613000 | H24: =X24 -> 611.5 | I24: =V24 -> 1.42 | J24: =W24 -> 868.33 | K24: =ROUND(AA24,2) -> 580.93 | L24: =ROUND(AB24,2) -> 597.27 | M24: =Y24 -> 43.8 | N24: =ROUND(Z24,2) -> 26783.7 | O24: 5407613000 | P24: КИТАЙ | Q24: HANGZHOU ZHONGFANG TEXTILE IMP/EXP.CO.,LTD | R24: FABRICS CONTAINING 85 % BY WT OR MORE OF NON-TEXTURED POLYESTER DYED YARNS: FABRIC FOR FURNITURE (BOUCLET) . composition 100% polyester/ТКАНИ СОДЕРЖАЩИЕ 85 МАС.% ИЛИ БОЛЕЕ НЕТЕКСТУРИРОВАННЫХ ПОЛИЭФИРНЫХ ОКРАШЕННЫХ НИТЕЙ: ТКАНЬ ДЛЯ МЕБЕЛИ (БУКЛЕ) . состав 100% полиэстер | S24: Noble 110 | T24: 5407610000 | U24: 15 | V24: 1.42 | W24: 868.33 | X24: 611.5 | Y24: 43.8 | Z24: =X24*Y24 -> 26783.7 | AA24: 580.925 | AB24: 597.269 | AC24: 01402 | AD24: ЕАЭС N RU Д-CN.РА02.В.67501/25 | AE24: 45742 | AF24: 47548 | AG24: HANGZHOU ZHONGFANG TEXTILE IMP./EXP. CO., LTD.
B25: 3 | C25: =U25 -> 12 | D25: =S25 -> Noble 624 | E25: =R25 -> FABRICS CONTAINING 85 % BY WT OR MORE OF NON-TEXTURED POLYESTER DYED YARNS: FABRIC FOR FURNITURE (BOUCLET) . composition 100% polyester/ТКАНИ СОДЕРЖАЩИЕ 85 МАС.% ИЛИ БОЛЕЕ НЕТЕКСТУРИРОВАННЫХ ПОЛИЭФИРНЫХ ОКРАШЕННЫХ НИТЕЙ: ТКАНЬ ДЛЯ МЕБЕЛИ (БУКЛЕ) . состав 100% полиэстер | F25: =T25 -> 5407610000 | G25: =O25 -> 5407613000 | H25: =X25 -> 507 | I25: =V25 -> 1.42 | J25: =W25 -> 719.94 | K25: =ROUND(AA25,2) -> 481.65 | L25: =ROUND(AB25,2) -> 494.73 | M25: =Y25 -> 43.8 | N25: =ROUND(Z25,2) -> 22206.6 | O25: 5407613000 | P25: КИТАЙ | Q25: HANGZHOU ZHONGFANG TEXTILE IMP/EXP.CO.,LTD | R25: FABRICS CONTAINING 85 % BY WT OR MORE OF NON-TEXTURED POLYESTER DYED YARNS: FABRIC FOR FURNITURE (BOUCLET) . composition 100% polyester/ТКАНИ СОДЕРЖАЩИЕ 85 МАС.% ИЛИ БОЛЕЕ НЕТЕКСТУРИРОВАННЫХ ПОЛИЭФИРНЫХ ОКРАШЕННЫХ НИТЕЙ: ТКАНЬ ДЛЯ МЕБЕЛИ (БУКЛЕ) . состав 100% полиэстер | S25: Noble 624 | T25: 5407610000 | U25: 12 | V25: 1.42 | W25: 719.94 | X25: 507 | Y25: 43.8 | Z25: =X25*Y25 -> 22206.6 | AA25: 481.65 | AB25: 494.7252 | AC25: 01402 | AD25: ЕАЭС N RU Д-CN.РА02.В.67501/25 | AE25: 45742 | AF25: 47548 | AG25: HANGZHOU ZHONGFANG TEXTILE IMP./EXP. CO., LTD.
B26: 4 | C26: =U26 -> 81 | D26: =S26 -> Omega 03 | E26: =R26 -> Upholstery fabric made of non-textured polyester threads, dyed, matting type, composition - 100% polyester Ткань мебельная обивочная из некстурированных полиэфирных нитей окрашенная, типа рогожка, состав - 100% полиэстер | F26: =T26 -> 5407610000 | G26: =O26 -> 5407613000 | H26: =X26 -> 3712.9 | I26: =V26 -> 1.44 | J26: =W26 -> 5346.576 | K26: =ROUND(AA26,2) -> 1559.42 | L26: =ROUND(AB26,2) -> 1640.4 | M26: =Y26 -> 9.5 | N26: =ROUND(Z26,2) -> 35272.55 | O26: 5407613000 | P26: КИТАЙ | Q26: HANGZHOU ZHONGFANG TEXTILE IMP/EXP.CO.,LTD | R26: Upholstery fabric made of non-textured polyester threads, dyed, matting type, composition - 100% polyester Ткань мебельная обивочная из некстурированных полиэфирных нитей окрашенная, типа рогожка, состав - 100% полиэстер | S26: Omega 03 | T26: 5407610000 | U26: 81 | V26: 1.44 | W26: 5346.576 | X26: 3712.9 | Y26: 9.5 | Z26: =X26*Y26 -> 35272.55 | AA26: 1559.418 | AB26: 1640.4018 | AC26: 01402 | AD26: ЕАЭС N RU Д-CN.РА02.В.67501/25 | AE26: 45742 | AF26: 47548 | AG26: HANGZHOU ZHONGFANG TEXTILE IMP./EXP. CO., LTD.
B27: 5 | C27: =U27 -> 35 | D27: =S27 -> Omega 62 | E27: =R27 -> Upholstery fabric made of non-textured polyester threads, dyed, matting type, composition - 100% polyester Ткань мебельная обивочная из некстурированных полиэфирных нитей окрашенная, типа рогожка, состав - 100% полиэстер | F27: =T27 -> 5407610000 | G27: =O27 -> 5407613000 | H27: =X27 -> 1630 | I27: =V27 -> 1.44 | J27: =W27 -> 2347.2 | K27: =ROUND(AA27,2) -> 684.6 | L27: =ROUND(AB27,2) -> 719.6 | M27: =Y27 -> 9.5 | N27: =ROUND(Z27,2) -> 15485 | O27: 5407613000 | P27: КИТАЙ | Q27: HANGZHOU ZHONGFANG TEXTILE IMP/EXP.CO.,LTD | R27: Upholstery fabric made of non-textured polyester threads, dyed, matting type, composition - 100% polyester Ткань мебельная обивочная из некстурированных полиэфирных нитей окрашенная, типа рогожка, состав - 100% полиэстер | S27: Omega 62 | T27: 5407610000 | U27: 35 | V27: 1.44 | W27: 2347.2 | X27: 1630 | Y27: 9.5 | Z27: =X27*Y27 -> 15485 | AA27: 684.6 | AB27: 719.595 | AC27: 01402 | AD27: ЕАЭС N RU Д-CN.РА02.В.67501/25 | AE27: 45742 | AF27: 47548 | AG27: HANGZHOU ZHONGFANG TEXTILE IMP./EXP. CO., LTD.
B28: 6 | C28: =U28 -> 6 | D28: =S28 -> Solo 794 | E28: =R28 -> OTHER FABRICS CONTAINING AT LEAST 85% BY WEIGHT SYNTHETIC THREADS, DYED: FABRIC FOR FURNITURE . composition 100% olefin/ПРОЧИЕ ТКАНИ, СОДЕРЖАЩИЕ ПО МАССЕ НЕ МЕНЕЕ 85% СИНТЕТИЧЕСКИХ НИТЕЙ, ОКРАШЕННЫЕ: ТКАНЬ ДЛЯ МЕБЕЛИ . состав 100% олефин | F28: =T28 -> 5407610000 | G28: =O28 -> 5407730000 | H28: =X28 -> 302.9 | I28: =V28 -> 1.48 | J28: =W28 -> 448.292 | K28: =ROUND(AA28,2) -> 99.96 | L28: =ROUND(AB28,2) -> 106.64 | M28: =Y28 -> 19 | N28: =ROUND(Z28,2) -> 5755.1 | O28: 5407730000 | P28: КИТАЙ | Q28: HANGZHOU ZHONGFANG TEXTILE IMP/EXP.CO.,LTD | R28: OTHER FABRICS CONTAINING AT LEAST 85% BY WEIGHT SYNTHETIC THREADS, DYED: FABRIC FOR FURNITURE . composition 100% olefin/ПРОЧИЕ ТКАНИ, СОДЕРЖАЩИЕ ПО МАССЕ НЕ МЕНЕЕ 85% СИНТЕТИЧЕСКИХ НИТЕЙ, ОКРАШЕННЫЕ: ТКАНЬ ДЛЯ МЕБЕЛИ . состав 100% олефин | S28: Solo 794 | T28: 5407610000 | U28: 6 | V28: 1.48 | W28: 448.292 | X28: 302.9 | Y28: 19 | Z28: =X28*Y28 -> 5755.1 | AA28: 99.957 | AB28: 106.6446 | AC28: 01402 | AD28: ЕАЭС N RU Д-CN.РА02.В.67501/25 | AE28: 45742 | AF28: 47548 | AG28: HANGZHOU ZHONGFANG TEXTILE IMP./EXP. CO., LTD.
B29: 7 | C29: =U29 -> 7 | D29: =S29 -> Solo 992 | E29: =R29 -> OTHER FABRICS CONTAINING AT LEAST 85% BY WEIGHT SYNTHETIC THREADS, DYED: FABRIC FOR FURNITURE . composition 100% olefin/ПРОЧИЕ ТКАНИ, СОДЕРЖАЩИЕ ПО МАССЕ НЕ МЕНЕЕ 85% СИНТЕТИЧЕСКИХ НИТЕЙ, ОКРАШЕННЫЕ: ТКАНЬ ДЛЯ МЕБЕЛИ . состав 100% олефин | F29: =T29 -> 5407610000 | G29: =O29 -> 5407730000 | H29: =X29 -> 344.1 | I29: =V29 -> 1.48 | J29: =W29 -> 509.268 | K29: =ROUND(AA29,2) -> 113.55 | L29: =ROUND(AB29,2) -> 121.36 | M29: =Y29 -> 19 | N29: =ROUND(Z29,2) -> 6537.9 | O29: 5407730000 | P29: КИТАЙ | Q29: HANGZHOU ZHONGFANG TEXTILE IMP/EXP.CO.,LTD | R29: OTHER FABRICS CONTAINING AT LEAST 85% BY WEIGHT SYNTHETIC THREADS, DYED: FABRIC FOR FURNITURE . composition 100% olefin/ПРОЧИЕ ТКАНИ, СОДЕРЖАЩИЕ ПО МАССЕ НЕ МЕНЕЕ 85% СИНТЕТИЧЕСКИХ НИТЕЙ, ОКРАШЕННЫЕ: ТКАНЬ ДЛЯ МЕБЕЛИ . состав 100% олефин | S29: Solo 992 | T29: 5407610000 | U29: 7 | V29: 1.48 | W29: 509.268 | X29: 344.1 | Y29: 19 | Z29: =X29*Y29 -> 6537.9 | AA29: 113.553 | AB29: 121.3552 | AC29: 01402 | AD29: ЕАЭС N RU Д-CN.РА02.В.67501/25 | AE29: 45742 | AF29: 47548 | AG29: HANGZHOU ZHONGFANG TEXTILE IMP./EXP. CO., LTD.
B30: 8 | C30: =U30 -> 26 | D30: =S30 -> Danco 100 | E30: =R30 -> SYNTHETIC FABRICS OF UNTEXTURED POLYESTER THREADS (COMPOSITION 100% POLYESTER), DYED/ТКАНИ СИНТЕТИЧЕСКИЕ ИЗ НЕТЕКСТУРИРОВАННЫХ ПОЛИЭФИРНЫХ НИТЕЙ (СОСТАВ 100% ПОЛИЭСТЕР) , ОКРАШЕННЫЕ | F30: =T30 -> 5801330000 | G30: =O30 -> 5407613000 | H30: =X30 -> 1268.5 | I30: =V30 -> 1.42 | J30: =W30 -> 1801.27 | K30: =ROUND(AA30,2) -> 558.14 | L30: =ROUND(AB30,2) -> 584.25 | M30: =Y30 -> 12.1 | N30: =ROUND(Z30,2) -> 15348.85 | O30: 5407613000 | P30: КИТАЙ | Q30: HANGZHOU ZHONGFANG TEXTILE IMP/EXP.CO.,LTD | R30: SYNTHETIC FABRICS OF UNTEXTURED POLYESTER THREADS (COMPOSITION 100% POLYESTER), DYED/ТКАНИ СИНТЕТИЧЕСКИЕ ИЗ НЕТЕКСТУРИРОВАННЫХ ПОЛИЭФИРНЫХ НИТЕЙ (СОСТАВ 100% ПОЛИЭСТЕР) , ОКРАШЕННЫЕ | S30: Danco 100 | T30: 5801330000 | U30: 26 | V30: 1.42 | W30: 1801.27 | X30: 1268.5 | Y30: 12.1 | Z30: =X30*Y30 -> 15348.85 | AA30: 558.14 | AB30: 584.2466 | AC30: 01402 | AD30: ЕАЭС N RU Д-CN.РА02.В.67501/25 | AE30: 45742 | AF30: 47548 | AG30: HANGZHOU ZHONGFANG TEXTILE IMP./EXP. CO., LTD.
B31: 9 | C31: =U31 -> 11 | D31: =S31 -> Danco 297 | E31: =R31 -> SYNTHETIC FABRICS OF UNTEXTURED POLYESTER THREADS (COMPOSITION 100% POLYESTER), DYED/ТКАНИ СИНТЕТИЧЕСКИЕ ИЗ НЕТЕКСТУРИРОВАННЫХ ПОЛИЭФИРНЫХ НИТЕЙ (СОСТАВ 100% ПОЛИЭСТЕР) , ОКРАШЕННЫЕ | F31: =T31 -> 5801330000 | G31: =O31 -> 5407613000 | H31: =X31 -> 535.7 | I31: =V31 -> 1.42 | J31: =W31 -> 760.694 | K31: =ROUND(AA31,2) -> 235.71 | L31: =ROUND(AB31,2) -> 246.75 | M31: =Y31 -> 12.1 | N31: =ROUND(Z31,2) -> 6481.97 | O31: 5407613000 | P31: КИТАЙ | Q31: HANGZHOU ZHONGFANG TEXTILE IMP/EXP.CO.,LTD | R31: SYNTHETIC FABRICS OF UNTEXTURED POLYESTER THREADS (COMPOSITION 100% POLYESTER), DYED/ТКАНИ СИНТЕТИЧЕСКИЕ ИЗ НЕТЕКСТУРИРОВАННЫХ ПОЛИЭФИРНЫХ НИТЕЙ (СОСТАВ 100% ПОЛИЭСТЕР) , ОКРАШЕННЫЕ | S31: Danco 297 | T31: 5801330000 | U31: 11 | V31: 1.42 | W31: 760.694 | X31: 535.7 | Y31: 12.1 | Z31: =X31*Y31 -> 6481.97 | AA31: 235.708 | AB31: 246.7531 | AC31: 01402 | AD31: ЕАЭС N RU Д-CN.РА02.В.67501/25 | AE31: 45742 | AF31: 47548 | AG31: HANGZHOU ZHONGFANG TEXTILE IMP./EXP. CO., LTD.
B32: 10 | C32: =U32 -> 7 | D32: =S32 -> Oscar 978 | E32: =R32 -> Upholstered furniture fabric made from chenille pile, such as chinillo, fine-weave weave, composition 100% polyester/Ткань мебельная обивочная из синели ворсовая, типа шинилл , мелкоузорчатого переплетения, состав 100% полиэстер | F32: =T32 -> 5801360000 | G32: =O32 -> 5801360000 | H32: =X32 -> 308.8 | I32: =V32 -> 1.43 | J32: =W32 -> 441.584 | K32: =ROUND(AA32,2) -> 197.63 | L32: =ROUND(AB32,2) -> 205 | M32: =Y32 -> 22.9 | N32: =ROUND(Z32,2) -> 7071.52 | O32: 5801360000 | P32: КИТАЙ | Q32: HANGZHOU ZHONGFANG TEXTILE IMP/EXP.CO.,LTD | R32: Upholstered furniture fabric made from chenille pile, such as chinillo, fine-weave weave, composition 100% polyester/Ткань мебельная обивочная из синели ворсовая, типа шинилл , мелкоузорчатого переплетения, состав 100% полиэстер | S32: Oscar 978 | T32: 5801360000 | U32: 7 | V32: 1.43 | W32: 441.584 | X32: 308.8 | Y32: 22.9 | Z32: =X32*Y32 -> 7071.52 | AA32: 197.632 | AB32: 205.0023 | AC32: 01402 | AD32: ЕАЭС N RU Д-CN.РА01.В.33381/23 | AE32: 44957 | AF32: 46775 | AG32: HANGZHOU ZHONGFANG TEXTILE IMP./EXP. CO., LTD.
B33: 11 | C33: =U33 -> 28 | D33: =S33 -> Umbra 110 | E33: =R33 -> Upholstery fabric, chenille, made from: polyester - 100%. Ткань мебельная обивочная ворсовая из химических синельных нитей, состав: 100% полиэстер | F33: =T33 -> 5801360000 | G33: =O33 -> 5801360000 | H33: =X33 -> 1001.6 | I33: =V33 -> 1.42 | J33: =W33 -> 1422.272 | K33: =ROUND(AA33,2) -> 480.77 | L33: =ROUND(AB33,2) -> 510 | M33: =Y33 -> 12.4 | N33: =ROUND(Z33,2) -> 12419.84 | O33: 5801360000 | P33: КИТАЙ | Q33: HANGZHOU ZHONGFANG TEXTILE IMP/EXP.CO.,LTD | R33: Upholstery fabric, chenille, made from: polyester - 100%. Ткань мебельная обивочная ворсовая из химических синельных нитей, состав: 100% полиэстер | S33: Umbra 110 | T33: 5801360000 | U33: 28 | V33: 1.42 | W33: 1422.272 | X33: 1001.6 | Y33: 12.4 | Z33: =X33*Y33 -> 12419.84 | AA33: 480.768 | AB33: 509.9972 | AC33: 01402 | AD33: ЕАЭС N RU Д-CN.РА01.В.33381/23 | AE33: 44957 | AF33: 46775 | AG33: HANGZHOU ZHONGFANG TEXTILE IMP./EXP. CO., LTD.
B34: 12 | C34: =U34 -> 10 | D34: =S34 -> Lambre 402 | E34: =R34 -> Knitting upholstery fabric with weft pile, made from: polyester - 100%. Полотно ворсовое трикотажное из химических нитей, с уточным ворсом, для обивки мебели. Состав: Полиэстер-100% | F34: =T34 -> 6001920000 | G34: =O34 -> 6001920000 | H34: =X34 -> 423.2 | I34: =V34 -> 1.42 | J34: =W34 -> 600.944 | K34: =ROUND(AA34,2) -> 304.7 | L34: =ROUND(AB34,2) -> 315.85 | M34: =Y34 -> 24.6 | N34: =ROUND(Z34,2) -> 10410.72 | O34: 6001920000 | P34: КИТАЙ | Q34: HANGZHOU ZHONGFANG TEXTILE IMP/EXP.CO.,LTD | R34: Knitting upholstery fabric with weft pile, made from: polyester - 100%. Полотно ворсовое трикотажное из химических нитей, с уточным ворсом, для обивки мебели. Состав: Полиэстер-100% | S34: Lambre 402 | T34: 6001920000 | U34: 10 | V34: 1.42 | W34: 600.944 | X34: 423.2 | Y34: 24.6 | Z34: =X34*Y34 -> 10410.72 | AA34: 304.704 | AB34: 315.852 | AC34: 01402 | AD34: ЕАЭС N RU Д-CN.РА01.В.33115/23 | AE34: 44957 | AF34: 46775 | AG34: HANGZHOU ZHONGFANG TEXTILE IMP./EXP. CO., LTD.
B35: 13 | C35: =U35 -> 17 | D35: =S35 -> Lambre 740 | E35: =R35 -> Knitting upholstery fabric with weft pile, made from: polyester - 100%. Полотно ворсовое трикотажное из химических нитей, с уточным ворсом, для обивки мебели. Состав: Полиэстер-100% | F35: =T35 -> 6001920000 | G35: =O35 -> 6001920000 | H35: =X35 -> 722.5 | I35: =V35 -> 1.42 | J35: =W35 -> 1025.95 | K35: =ROUND(AA35,2) -> 520.2 | L35: =ROUND(AB35,2) -> 539.15 | M35: =Y35 -> 24.6 | N35: =ROUND(Z35,2) -> 17773.5 | O35: 6001920000 | P35: КИТАЙ | Q35: HANGZHOU ZHONGFANG TEXTILE IMP/EXP.CO.,LTD | R35: Knitting upholstery fabric with weft pile, made from: polyester - 100%. Полотно ворсовое трикотажное из химических нитей, с уточным ворсом, для обивки мебели. Состав: Полиэстер-100% | S35: Lambre 740 | T35: 6001920000 | U35: 17 | V35: 1.42 | W35: 1025.95 | X35: 722.5 | Y35: 24.6 | Z35: =X35*Y35 -> 17773.5 | AA35: 520.2 | AB35: 539.1516 | AC35: 01402 | AD35: ЕАЭС N RU Д-CN.РА01.В.33115/23 | AE35: 44957 | AF35: 46775 | AG35: HANGZHOU ZHONGFANG TEXTILE IMP./EXP. CO., LTD.
B36: Total/Итого: | C36: =SUM(C23:C35) -> 263 | H36: =SUM(H23:H35) -> 11671.6 | J36: =SUM(J23:J35) -> 16719.409 | K36: =SUM(K23:K35) -> 6026.26 | L36: =SUM(L23:L35) -> 6300 | N36: =SUM(N23:N35) -> 188362.5
C38: Продавец: | I38: Seller:
C39: HANGZHOU ZHONGFANG TEXTILE IMP./EXP. CO., LTD. | I39: HANGZHOU ZHONGFANG TEXTILE IMP./EXP. CO., LTD
C40: Адрес:NO.756-2,RENMIN AVENUE,NANYUAN STREET,YUHANG DISTRICT, | I40: Address:NO.756-2,RENMIN AVENUE,NANYUAN STREET,YUHANG DISTRICT,
C41: HANGZHOU, ZHEJIANG PROVINCE CHINA | I41: HANGZHOU, ZHEJIANG PROVINCE CHINA
C42: Адрес склада:West 1/F Bld 3, No. 503 Shunfeng Road, Qianjiang Economic Development Zone, Yuhang District, Hangzhou, Zhejiang Province, China | I42: Warehouse address:West 1/F Bld 3, No. 503 Shunfeng Road, Qianjiang Economic Development Zone, Yuhang District, Hangzhou, Zhejiang Province, China
C43: Телефон: +86-571-86255881 | I43: Tel.: +86-571-86255881
C44: Вебсайт:http://www.zhongfanghz.cn/ | I44: Website:http://www.zhongfanghz.cn/
C45: E-mail: liuzhihui@zhongfanghz.cn | I45: Email: liuzhihui@zhongfanghz.cn
C46: Банковские реквизиты: | I46: Bank details:
...

Sheet описание
B1: 杭 州 中 纺 进 出 口 有 限 公 司
B2: HANGZHOU ZHONGFANG TEXTILE IMP./EXP. CO., LTD.
B3: NO.756-2,RENMIN AVENUE,NANYUAN STREET, LINPING DISTRICT,HANGZHOU, ZHEJIANG PROVINCE CHINA, tel: +86-571-86255881, E-mail: liuzhihui@zhongfanghz.cn
B4: www.zhongfanghz.cn
B5: ="DESCRIPTION FOR SPECIFICATION №"&'инвойс 1'!L9&" dd "&'инвойс 1'!L11 -> DESCRIPTION FOR SPECIFICATION №ZFRMB26148-626-1 dd Aug.19,2026
B6: Contract/Контракт №：SM-LU2 dated 23.11.2018
B7: Manufactor and Seller / Производитель и Продавец:
B8: HANGZHOU ZHONGFANG TEXTILE IMP./EXP. CO., LTD.
B9: Address/Адрес:
B10: NO.756-2,RENMIN AVENUE,NANYUAN STREET, LINPING DISTRICT,HANGZHOU, ZHEJIANG PROVINCE CHINA, tel: +86-571-86255881, E-mail: liuzhihui@zhongfanghz.cn
B12: № | C12: Q-Ty Rolls / Кол-во рулонов. | D12: Art./Артикул | E12: Product name / Наименование товара | F12: HS code / Код гармонизированной системы | G12: Customs code / Таможенный код | H12: Q-ty meters / Кол-во погонных метров | I12: Widht, m / Ширина, м | J12: Q-ty m2 / Кол-во кв.м | K12: N.W, kg / Вес Нетто, кг | L12: G.W, kg / Вес Брутто, кг | M12: Price per meter ￥/ Цена за пог. метр, Юань | N12: Total price, Y / Цена, Юань
B13: ='инвойс 1'!B23 -> 1 | C13: 15 | D13: ='инвойс 1'!D23 -> Melange 928 | E13: ='инвойс 1'!E23 -> Upholstery fabric from textured polyether yarns of different colors, made from: polyester - 100%. Ткань мебельная обивочная из текстурированных полиэфирных нитей разных цветов, состав полиэстер 100% | F13: ='инвойс 1'!F23 -> 5407530000 | G13: ='инвойс 1'!G23 -> 5407530000 | H13: 513.4 | I13: =J13/H13 -> 1.41 | J13: 723.894 | K13: 415.85 | L13: 430 | M13: 34.25 | N13: 17583.95 | Q13: =M13*H13 -> 17583.95 | R13: =ROUND(Q13,2) -> 17583.95
B14: ='инвойс 1'!B24 -> 2 | C14: 15 | D14: ='инвойс 1'!D24 -> Noble 110 | E14: ='инвойс 1'!E24 -> FABRICS CONTAINING 85 % BY WT OR MORE OF NON-TEXTURED POLYESTER DYED YARNS: FABRIC FOR FURNITURE (BOUCLET) . composition 100% polyester/ТКАНИ СОДЕРЖАЩИЕ 85 МАС.% ИЛИ БОЛЕЕ НЕТЕКСТУРИРОВАННЫХ ПОЛИЭФИРНЫХ ОКРАШЕННЫХ НИТЕЙ: ТКАНЬ ДЛЯ МЕБЕЛИ (БУКЛЕ) . состав 100% полиэстер | F14: ='инвойс 1'!F24 -> 5407610000 | G14: ='инвойс 1'!G24 -> 5407613000
B15: ='инвойс 1'!B25 -> 3 | C15: 15 | D15: ='инвойс 1'!D25 -> Noble 624 | E15: ='инвойс 1'!E25 -> FABRICS CONTAINING 85 % BY WT OR MORE OF NON-TEXTURED POLYESTER DYED YARNS: FABRIC FOR FURNITURE (BOUCLET) . composition 100% polyester/ТКАНИ СОДЕРЖАЩИЕ 85 МАС.% ИЛИ БОЛЕЕ НЕТЕКСТУРИРОВАННЫХ ПОЛИЭФИРНЫХ ОКРАШЕННЫХ НИТЕЙ: ТКАНЬ ДЛЯ МЕБЕЛИ (БУКЛЕ) . состав 100% полиэстер | F15: ='инвойс 1'!F25 -> 5407610000 | G15: ='инвойс 1'!G25 -> 5407613000
B16: ='инвойс 1'!B26 -> 4 | C16: 15 | D16: ='инвойс 1'!D26 -> Omega 03 | E16: ='инвойс 1'!E26 -> Upholstery fabric made of non-textured polyester threads, dyed, matting type, composition - 100% polyester Ткань мебельная обивочная из некстурированных полиэфирных нитей окрашенная, типа рогожка, состав - 100% полиэстер | F16: ='инвойс 1'!F26 -> 5407610000 | G16: ='инвойс 1'!G26 -> 5407613000 | H16: 513.4 | I16: =J16/H16 -> 1.41 | J16: 723.894 | K16: 415.85 | L16: 430 | M16: 34.25 | N16: 17583.95 | Q16: =M16*H16 -> 17583.95 | R16: =ROUND(Q16,2) -> 17583.95
B17: ='инвойс 1'!B27 -> 5 | C17: 15 | D17: ='инвойс 1'!D27 -> Omega 62 | E17: ='инвойс 1'!E27 -> Upholstery fabric made of non-textured polyester threads, dyed, matting type, composition - 100% polyester Ткань мебельная обивочная из некстурированных полиэфирных нитей окрашенная, типа рогожка, состав - 100% полиэстер | F17: ='инвойс 1'!F27 -> 5407610000 | G17: ='инвойс 1'!G27 -> 5407613000
B18: ='инвойс 1'!B28 -> 6 | C18: 15 | D18: ='инвойс 1'!D28 -> Solo 794 | E18: ='инвойс 1'!E28 -> OTHER FABRICS CONTAINING AT LEAST 85% BY WEIGHT SYNTHETIC THREADS, DYED: FABRIC FOR FURNITURE . composition 100% olefin/ПРОЧИЕ ТКАНИ, СОДЕРЖАЩИЕ ПО МАССЕ НЕ МЕНЕЕ 85% СИНТЕТИЧЕСКИХ НИТЕЙ, ОКРАШЕННЫЕ: ТКАНЬ ДЛЯ МЕБЕЛИ . состав 100% олефин | F18: ='инвойс 1'!F28 -> 5407610000 | G18: ='инвойс 1'!G28 -> 5407730000
B19: ='инвойс 1'!B29 -> 7 | C19: 15 | D19: ='инвойс 1'!D29 -> Solo 992 | E19: ='инвойс 1'!E29 -> OTHER FABRICS CONTAINING AT LEAST 85% BY WEIGHT SYNTHETIC THREADS, DYED: FABRIC FOR FURNITURE . composition 100% olefin/ПРОЧИЕ ТКАНИ, СОДЕРЖАЩИЕ ПО МАССЕ НЕ МЕНЕЕ 85% СИНТЕТИЧЕСКИХ НИТЕЙ, ОКРАШЕННЫЕ: ТКАНЬ ДЛЯ МЕБЕЛИ . состав 100% олефин | F19: ='инвойс 1'!F29 -> 5407610000 | G19: ='инвойс 1'!G29 -> 5407730000 | H19: 513.4 | I19: =J19/H19 -> 1.41 | J19: 723.894 | K19: 415.85 | L19: 430 | M19: 34.25 | N19: 17583.95 | Q19: =M19*H19 -> 17583.95 | R19: =ROUND(Q19,2) -> 17583.95
B20: ='инвойс 1'!B30 -> 8 | C20: 15 | D20: ='инвойс 1'!D30 -> Danco 100 | E20: ='инвойс 1'!E30 -> SYNTHETIC FABRICS OF UNTEXTURED POLYESTER THREADS (COMPOSITION 100% POLYESTER), DYED/ТКАНИ СИНТЕТИЧЕСКИЕ ИЗ НЕТЕКСТУРИРОВАННЫХ ПОЛИЭФИРНЫХ НИТЕЙ (СОСТАВ 100% ПОЛИЭСТЕР) , ОКРАШЕННЫЕ | F20: ='инвойс 1'!F30 -> 5801330000 | G20: ='инвойс 1'!G30 -> 5407613000
B21: ='инвойс 1'!B31 -> 9 | C21: 15 | D21: ='инвойс 1'!D31 -> Danco 297 | E21: ='инвойс 1'!E31 -> SYNTHETIC FABRICS OF UNTEXTURED POLYESTER THREADS (COMPOSITION 100% POLYESTER), DYED/ТКАНИ СИНТЕТИЧЕСКИЕ ИЗ НЕТЕКСТУРИРОВАННЫХ ПОЛИЭФИРНЫХ НИТЕЙ (СОСТАВ 100% ПОЛИЭСТЕР) , ОКРАШЕННЫЕ | F21: ='инвойс 1'!F31 -> 5801330000 | G21: ='инвойс 1'!G31 -> 5407613000
B22: ='инвойс 1'!B32 -> 10 | C22: 15 | D22: ='инвойс 1'!D32 -> Oscar 978 | E22: ='инвойс 1'!E32 -> Upholstered furniture fabric made from chenille pile, such as chinillo, fine-weave weave, composition 100% polyester/Ткань мебельная обивочная из синели ворсовая, типа шинилл , мелкоузорчатого переплетения, состав 100% полиэстер | F22: ='инвойс 1'!F32 -> 5801360000 | G22: ='инвойс 1'!G32 -> 5801360000
B23: ='инвойс 1'!B33 -> 11 | C23: 15 | D23: ='инвойс 1'!D33 -> Umbra 110 | E23: ='инвойс 1'!E33 -> Upholstery fabric, chenille, made from: polyester - 100%. Ткань мебельная обивочная ворсовая из химических синельных нитей, состав: 100% полиэстер | F23: ='инвойс 1'!F33 -> 5801360000 | G23: ='инвойс 1'!G33 -> 5801360000
B24: ='инвойс 1'!B34 -> 12 | C24: 15 | D24: ='инвойс 1'!D34 -> Lambre 402 | E24: ='инвойс 1'!E34 -> Knitting upholstery fabric with weft pile, made from: polyester - 100%. Полотно ворсовое трикотажное из химических нитей, с уточным ворсом, для обивки мебели. Состав: Полиэстер-100% | F24: ='инвойс 1'!F34 -> 6001920000 | G24: ='инвойс 1'!G34 -> 6001920000 | H24: 513.4 | I24: =J24/H24 -> 1.41 | J24: 723.894 | K24: 415.85 | L24: 430 | M24: 34.25 | N24: 17583.95 | Q24: =M24*H24 -> 17583.95 | R24: =ROUND(Q24,2) -> 17583.95
B25: ='инвойс 1'!B35 -> 13 | C25: 15 | D25: ='инвойс 1'!D35 -> Lambre 740 | E25: ='инвойс 1'!E35 -> Knitting upholstery fabric with weft pile, made from: polyester - 100%. Полотно ворсовое трикотажное из химических нитей, с уточным ворсом, для обивки мебели. Состав: Полиэстер-100% | F25: ='инвойс 1'!F35 -> 6001920000 | G25: ='инвойс 1'!G35 -> 6001920000
C26: HANGZHOU ZHONGFANG TEXTILE IMP./EXP. CO., LTD.
C27: Адрес:NO.756-2,RENMIN AVENUE,NANYUAN STREET,YUHANG DISTRICT, | I27: HANGZHOU ZHONGFANG TEXTILE IMP./EXP. CO., LTD
C28: HANGZHOU, ZHEJIANG PROVINCE CHINA | I28: Address:NO.756-2,RENMIN AVENUE,NANYUAN STREET,YUHANG DISTRICT,
C29: Адрес склада:West 1/F Bld 3, No. 503 Shunfeng Road, Qianjiang Economic Development Zone, Yuhang District, Hangzhou, Zhejiang Province, China | I29: HANGZHOU, ZHEJIANG PROVINCE CHINA
C30: Телефон: +86-571-86255881 | I30: Warehouse address:West 1/F Bld 3, No. 503 Shunfeng Road, Qianjiang Economic Development Zone, Yuhang District, Hangzhou, Zhejiang Province, China
C31: Вебсайт:http://www.zhongfanghz.cn/ | I31: Tel.: +86-571-86255881
C32: E-mail: liuzhihui@zhongfanghz.cn | I32: Website:http://www.zhongfanghz.cn/
I33: Email: liuzhihui@zhongfanghz.cn
C34: Высший руководитель_________________Liu Zhihui
I35: Top manager______________________Liu Zhihui
